try {
    const a = 1
} catch (error) {

}
console.log(a)